Workbook

Sheet Prices
A1: Date | B1: ONGC | C1: HAL | D1: TCS | E1: BPCL | F1: GOLDBEES | G1: NIFTY
A2: =IFERROR(__xludf.DUMMYFUNCTION("GOOGLEFINANCE(""NSE:ONGC"",""close"",DATE(2026,1,1),TODAY(),""DAILY"")"),"Date") -> Date | B2: =IFERROR(__xludf.DUMMYFUNCTION("""COMPUTED_VALUE"""),"Close") -> Close | C2: =IFERROR(__xludf.DUMMYFUNCTION("INDEX(GOOGLEFINANCE(""NSE:HAL"",""close"",DATE(2026,1,1),TODAY(),""DAILY""),0,2)"),"Close") -> Close | D2: =IFERROR(__xludf.DUMMYFUNCTION("INDEX(GOOGLEFINANCE(""NSE:TCS"",""close"",DATE(2026,1,1),TODAY(),""DAILY""),0,2)"),"Close") -> Close | E2: =IFERROR(__xludf.DUMMYFUNCTION("INDEX(GOOGLEFINANCE(""NSE:BPCL"",""close"",DATE(2026,1,1),TODAY(),""DAILY""),0,2)"),"Close") -> Close | F2: =IFERROR(__xludf.DUMMYFUNCTION("INDEX(GOOGLEFINANCE(""NSE:GOLDBEES"",""close"",DATE(2026,1,1),TODAY(),""DAILY""),0,2)"),"Close") -> Close | G2: =IFERROR(__xludf.DUMMYFUNCTION("INDEX(GOOGLEFINANCE(""INDEXNSE:NIFTY_50"",""close"",DATE(2026,1,1),TODAY(),""DAILY""),0,2)"),"Close") -> Close
A3: =IFERROR(__xludf.DUMMYFUNCTION("""COMPUTED_VALUE"""),46023.64583333333) -> 46023.646 | B3: =IFERROR(__xludf.DUMMYFUNCTION("""COMPUTED_VALUE"""),237.94) -> 237.94 | C3: =IFERROR(__xludf.DUMMYFUNCTION("""COMPUTED_VALUE"""),4397.9) -> 4397.9 | D3: =IFERROR(__xludf.DUMMYFUNCTION("""COMPUTED_VALUE"""),3227.4) -> 3227.4 | E3: =IFERROR(__xludf.DUMMYFUNCTION("""COMPUTED_VALUE"""),381.5) -> 381.5 | F3: =IFERROR(__xludf.DUMMYFUNCTION("""COMPUTED_VALUE"""),110.52) -> 110.52 | G3: =IFERROR(__xludf.DUMMYFUNCTION("""COMPUTED_VALUE"""),26146.55) -> 26146.55
A4: =IFERROR(__xludf.DUMMYFUNCTION("""COMPUTED_VALUE"""),46024.64583333333) -> 46024.646 | B4: =IFERROR(__xludf.DUMMYFUNCTION("""COMPUTED_VALUE"""),241.46) -> 241.46 | C4: =IFERROR(__xludf.DUMMYFUNCTION("""COMPUTED_VALUE"""),4417.8) -> 4417.8 | D4: =IFERROR(__xludf.DUMMYFUNCTION("""COMPUTED_VALUE"""),3250.7) -> 3250.7 | E4: =IFERROR(__xludf.DUMMYFUNCTION("""COMPUTED_VALUE"""),381.45) -> 381.45 | F4: =IFERROR(__xludf.DUMMYFUNCTION("""COMPUTED_VALUE"""),111.82) -> 111.82 | G4: =IFERROR(__xludf.DUMMYFUNCTION("""COMPUTED_VALUE"""),26328.55) -> 26328.55
A5: =IFERROR(__xludf.DUMMYFUNCTION("""COMPUTED_VALUE"""),46027.64583333333) -> 46027.646 | B5: =IFERROR(__xludf.DUMMYFUNCTION("""COMPUTED_VALUE"""),238.09) -> 238.09 | C5: =IFERROR(__xludf.DUMMYFUNCTION("""COMPUTED_VALUE"""),4526.1) -> 4526.1 | D5: =IFERROR(__xludf.DUMMYFUNCTION("""COMPUTED_VALUE"""),3216.1) -> 3216.1 | E5: =IFERROR(__xludf.DUMMYFUNCTION("""COMPUTED_VALUE"""),377.9) -> 377.9 | F5: =IFERROR(__xludf.DUMMYFUNCTION("""COMPUTED_VALUE"""),112.92) -> 112.92 | G5: =IFERROR(__xludf.DUMMYFUNCTION("""COMPUTED_VALUE"""),26250.3) -> 26250.3
A6: =IFERROR(__xludf.DUMMYFUNCTION("""COMPUTED_VALUE"""),46028.64583333333) -> 46028.646 | B6: =IFERROR(__xludf.DUMMYFUNCTION("""COMPUTED_VALUE"""),241.89) -> 241.89 | C6: =IFERROR(__xludf.DUMMYFUNCTION("""COMPUTED_VALUE"""),4516.0) -> 4516 | D6: =IFERROR(__xludf.DUMMYFUNCTION("""COMPUTED_VALUE"""),3255.8) -> 3255.8 | E6: =IFERROR(__xludf.DUMMYFUNCTION("""COMPUTED_VALUE"""),370.8) -> 370.8 | F6: =IFERROR(__xludf.DUMMYFUNCTION("""COMPUTED_VALUE"""),113.14) -> 113.14 | G6: =IFERROR(__xludf.DUMMYFUNCTION("""COMPUTED_VALUE"""),26178.7) -> 26178.7
A7: =IFERROR(__xludf.DUMMYFUNCTION("""COMPUTED_VALUE"""),46029.64583333333) -> 46029.646 | B7: =IFERROR(__xludf.DUMMYFUNCTION("""COMPUTED_VALUE"""),239.06) -> 239.06 | C7: =IFERROR(__xludf.DUMMYFUNCTION("""COMPUTED_VALUE"""),4525.1) -> 4525.1 | D7: =IFERROR(__xludf.DUMMYFUNCTION("""COMPUTED_VALUE"""),3295.6) -> 3295.6 | E7: =IFERROR(__xludf.DUMMYFUNCTION("""COMPUTED_VALUE"""),368.2) -> 368.2 | F7: =IFERROR(__xludf.DUMMYFUNCTION("""COMPUTED_VALUE"""),112.91) -> 112.91 | G7: =IFERROR(__xludf.DUMMYFUNCTION("""COMPUTED_VALUE"""),26140.75) -> 26140.75
A8: =IFERROR(__xludf.DUMMYFUNCTION("""COMPUTED_VALUE"""),46030.64583333333) -> 46030.646 | B8: =IFERROR(__xludf.DUMMYFUNCTION("""COMPUTED_VALUE"""),231.42) -> 231.42 | C8: =IFERROR(__xludf.DUMMYFUNCTION("""COMPUTED_VALUE"""),4479.8) -> 4479.8 | D8: =IFERROR(__xludf.DUMMYFUNCTION("""COMPUTED_VALUE"""),3203.9) -> 3203.9 | E8: =IFERROR(__xludf.DUMMYFUNCTION("""COMPUTED_VALUE"""),354.55) -> 354.55 | F8: =IFERROR(__xludf.DUMMYFUNCTION("""COMPUTED_VALUE"""),112.29) -> 112.29 | G8: =IFERROR(__xludf.DUMMYFUNCTION("""COMPUTED_VALUE"""),25876.85) -> 25876.85
A9: =IFERROR(__xludf.DUMMYFUNCTION("""COMPUTED_VALUE"""),46031.64583333333) -> 46031.646 | B9: =IFERROR(__xludf.DUMMYFUNCTION("""COMPUTED_VALUE"""),234.09) -> 234.09 | C9: =IFERROR(__xludf.DUMMYFUNCTION("""COMPUTED_VALUE"""),4462.1) -> 4462.1 | D9: =IFERROR(__xludf.DUMMYFUNCTION("""COMPUTED_VALUE"""),3207.8) -> 3207.8 | E9: =IFERROR(__xludf.DUMMYFUNCTION("""COMPUTED_VALUE"""),354.15) -> 354.15 | F9: =IFERROR(__xludf.DUMMYFUNCTION("""COMPUTED_VALUE"""),113.61) -> 113.61 | G9: =IFERROR(__xludf.DUMMYFUNCTION("""COMPUTED_VALUE"""),25683.3) -> 25683.3
A10: =IFERROR(__xludf.DUMMYFUNCTION("""COMPUTED_VALUE"""),46034.64583333333) -> 46034.646 | B10: =IFERROR(__xludf.DUMMYFUNCTION("""COMPUTED_VALUE"""),235.71) -> 235.71 | C10: =IFERROR(__xludf.DUMMYFUNCTION("""COMPUTED_VALUE"""),4518.4) -> 4518.4 | D10: =IFERROR(__xludf.DUMMYFUNCTION("""COMPUTED_VALUE"""),3239.6) -> 3239.6 | E10: =IFERROR(__xludf.DUMMYFUNCTION("""COMPUTED_VALUE"""),358.75) -> 358.75 | F10: =IFERROR(__xludf.DUMMYFUNCTION("""COMPUTED_VALUE"""),116.76) -> 116.76 | G10: =IFERROR(__xludf.DUMMYFUNCTION("""COMPUTED_VALUE"""),25790.25) -> 25790.25
A11: =IFERROR(__xludf.DUMMYFUNCTION("""COMPUTED_VALUE"""),46035.64583333333) -> 46035.646 | B11: =IFERROR(__xludf.DUMMYFUNCTION("""COMPUTED_VALUE"""),243.78) -> 243.78 | C11: =IFERROR(__xludf.DUMMYFUNCTION("""COMPUTED_VALUE"""),4452.4) -> 4452.4 | D11: =IFERROR(__xludf.DUMMYFUNCTION("""COMPUTED_VALUE"""),3268.0) -> 3268 | E11: =IFERROR(__xludf.DUMMYFUNCTION("""COMPUTED_VALUE"""),355.1) -> 355.1 | F11: =IFERROR(__xludf.DUMMYFUNCTION("""COMPUTED_VALUE"""),116.37) -> 116.37 | G11: =IFERROR(__xludf.DUMMYFUNCTION("""COMPUTED_VALUE"""),25732.3) -> 25732.3
A12: =IFERROR(__xludf.DUMMYFUNCTION("""COMPUTED_VALUE"""),46036.64583333333) -> 46036.646 | B12: =IFERROR(__xludf.DUMMYFUNCTION("""COMPUTED_VALUE"""),248.23) -> 248.23 | C12: =IFERROR(__xludf.DUMMYFUNCTION("""COMPUTED_VALUE"""),4461.4) -> 4461.4 | D12: =IFERROR(__xludf.DUMMYFUNCTION("""COMPUTED_VALUE"""),3192.5) -> 3192.5 | E12: =IFERROR(__xludf.DUMMYFUNCTION("""COMPUTED_VALUE"""),356.9) -> 356.9 | F12: =IFERROR(__xludf.DUMMYFUNCTION("""COMPUTED_VALUE"""),118.01) -> 118.01 | G12: =IFERROR(__xludf.DUMMYFUNCTION("""COMPUTED_VALUE"""),25665.6) -> 25665.6
A13: =IFERROR(__xludf.DUMMYFUNCTION("""COMPUTED_VALUE"""),46038.64583333333) -> 46038.646 | B13: =IFERROR(__xludf.DUMMYFUNCTION("""COMPUTED_VALUE"""),247.17) -> 247.17 | C13: =IFERROR(__xludf.DUMMYFUNCTION("""COMPUTED_VALUE"""),4428.7) -> 4428.7 | D13: =IFERROR(__xludf.DUMMYFUNCTION("""COMPUTED_VALUE"""),3206.7) -> 3206.7 | E13: =IFERROR(__xludf.DUMMYFUNCTION("""COMPUTED_VALUE"""),363.2) -> 363.2 | F13: =IFERROR(__xludf.DUMMYFUNCTION("""COMPUTED_VALUE"""),117.78) -> 117.78 | G13: =IFERROR(__xludf.DUMMYFUNCTION("""COMPUTED_VALUE"""),25694.35) -> 25694.35
A14: =IFERROR(__xludf.DUMMYFUNCTION("""COMPUTED_VALUE"""),46041.64583333333) -> 46041.646 | B14: =IFERROR(__xludf.DUMMYFUNCTION("""COMPUTED_VALUE"""),243.11) -> 243.11 | C14: =IFERROR(__xludf.DUMMYFUNCTION("""COMPUTED_VALUE"""),4504.3) -> 4504.3 | D14: =IFERROR(__xludf.DUMMYFUNCTION("""COMPUTED_VALUE"""),3163.6) -> 3163.6 | E14: =IFERROR(__xludf.DUMMYFUNCTION("""COMPUTED_VALUE"""),361.25) -> 361.25 | F14: =IFERROR(__xludf.DUMMYFUNCTION("""COMPUTED_VALUE"""),121.1) -> 121.1 | G14: =IFERROR(__xludf.DUMMYFUNCTION("""COMPUTED_VALUE"""),25585.5) -> 25585.5
A15: =IFERROR(__xludf.DUMMYFUNCTION("""COMPUTED_VALUE"""),46042.64583333333) -> 46042.646 | B15: =IFERROR(__xludf.DUMMYFUNCTION("""COMPUTED_VALUE"""),240.39) -> 240.39 | C15: =IFERROR(__xludf.DUMMYFUNCTION("""COMPUTED_VALUE"""),4355.2) -> 4355.2 | D15: =IFERROR(__xludf.DUMMYFUNCTION("""COMPUTED_VALUE"""),3102.3) -> 3102.3 | E15: =IFERROR(__xludf.DUMMYFUNCTION("""COMPUTED_VALUE"""),355.2) -> 355.2 | F15: =IFERROR(__xludf.DUMMYFUNCTION("""COMPUTED_VALUE"""),125.86) -> 125.86 | G15: =IFERROR(__xludf.DUMMYFUNCTION("""COMPUTED_VALUE"""),25232.5) -> 25232.5
A16: =IFERROR(__xludf.DUMMYFUNCTION("""COMPUTED_VALUE"""),46043.64583333333) -> 46043.646 | B16: =IFERROR(__xludf.DUMMYFUNCTION("""COMPUTED_VALUE"""),242.37) -> 242.37 | C16: =IFERROR(__xludf.DUMMYFUNCTION("""COMPUTED_VALUE"""),4259.4) -> 4259.4 | D16: =IFERROR(__xludf.DUMMYFUNCTION("""COMPUTED_VALUE"""),3122.6) -> 3122.6 | E16: =IFERROR(__xludf.DUMMYFUNCTION("""COMPUTED_VALUE"""),351.95) -> 351.95 | F16: =IFERROR(__xludf.DUMMYFUNCTION("""COMPUTED_VALUE"""),134.97) -> 134.97 | G16: =IFERROR(__xludf.DUMMYFUNCTION("""COMPUTED_VALUE"""),25157.5) -> 25157.5
A17: =IFERROR(__xludf.DUMMYFUNCTION("""COMPUTED_VALUE"""),46044.64583333333) -> 46044.646 | B17: =IFERROR(__xludf.DUMMYFUNCTION("""COMPUTED_VALUE"""),244.01) -> 244.01 | C17: =IFERROR(__xludf.DUMMYFUNCTION("""COMPUTED_VALUE"""),4353.2) -> 4353.2 | D17: =IFERROR(__xludf.DUMMYFUNCTION("""COMPUTED_VALUE"""),3150.4) -> 3150.4 | E17: =IFERROR(__xludf.DUMMYFUNCTION("""COMPUTED_VALUE"""),354.15) -> 354.15 | F17: =IFERROR(__xludf.DUMMYFUNCTION("""COMPUTED_VALUE"""),124.34) -> 124.34 | G17: =IFERROR(__xludf.DUMMYFUNCTION("""COMPUTED_VALUE"""),25289.9) -> 25289.9
A18: =IFERROR(__xludf.DUMMYFUNCTION("""COMPUTED_VALUE"""),46045.64583333333) -> 46045.646 | B18: =IFERROR(__xludf.DUMMYFUNCTION("""COMPUTED_VALUE"""),245.47) -> 245.47 | C18: =IFERROR(__xludf.DUMMYFUNCTION("""COMPUTED_VALUE"""),4305.7) -> 4305.7 | D18: =IFERROR(__xludf.DUMMYFUNCTION("""COMPUTED_VALUE"""),3162.5) -> 3162.5 | E18: =IFERROR(__xludf.DUMMYFUNCTION("""COMPUTED_VALUE"""),349.15) -> 349.15 | F18: =IFERROR(__xludf.DUMMYFUNCTION("""COMPUTED_VALUE"""),127.42) -> 127.42 | G18: =IFERROR(__xludf.DUMMYFUNCTION("""COMPUTED_VALUE"""),25048.65) -> 25048.65
A19: =IFERROR(__xludf.DUMMYFUNCTION("""COMPUTED_VALUE"""),46049.64583333333) -> 46049.646 | B19: =IFERROR(__xludf.DUMMYFUNCTION("""COMPUTED_VALUE"""),247.95) -> 247.95 | C19: =IFERROR(__xludf.DUMMYFUNCTION("""COMPUTED_VALUE"""),4348.5) -> 4348.5 | D19: =IFERROR(__xludf.DUMMYFUNCTION("""COMPUTED_VALUE"""),3158.0) -> 3158 | E19: =IFERROR(__xludf.DUMMYFUNCTION("""COMPUTED_VALUE"""),357.4) -> 357.4 | F19: =IFERROR(__xludf.DUMMYFUNCTION("""COMPUTED_VALUE"""),131.45) -> 131.45 | G19: =IFERROR(__xludf.DUMMYFUNCTION("""COMPUTED_VALUE"""),25175.4) -> 25175.4
A20: =IFERROR(__xludf.DUMMYFUNCTION("""COMPUTED_VALUE"""),46050.64583333333) -> 46050.646 | B20: =IFERROR(__xludf.DUMMYFUNCTION("""COMPUTED_VALUE"""),268.58) -> 268.58 | C20: =IFERROR(__xludf.DUMMYFUNCTION("""COMPUTED_VALUE"""),4624.0) -> 4624 | D20: =IFERROR(__xludf.DUMMYFUNCTION("""COMPUTED_VALUE"""),3200.1) -> 3200.1 | E20: =IFERROR(__xludf.DUMMYFUNCTION("""COMPUTED_VALUE"""),362.35) -> 362.35 | F20: =IFERROR(__xludf.DUMMYFUNCTION("""COMPUTED_VALUE"""),135.82) -> 135.82 | G20: =IFERROR(__xludf.DUMMYFUNCTION("""COMPUTED_VALUE"""),25342.75) -> 25342.75
A21: =IFERROR(__xludf.DUMMYFUNCTION("""COMPUTED_VALUE"""),46051.64583333333) -> 46051.646 | B21: =IFERROR(__xludf.DUMMYFUNCTION("""COMPUTED_VALUE"""),275.39) -> 275.39 | C21: =IFERROR(__xludf.DUMMYFUNCTION("""COMPUTED_VALUE"""),4601.0) -> 4601 | D21: =IFERROR(__xludf.DUMMYFUNCTION("""COMPUTED_VALUE"""),3144.4) -> 3144.4 | E21: =IFERROR(__xludf.DUMMYFUNCTION("""COMPUTED_VALUE"""),366.95) -> 366.95 | F21: =IFERROR(__xludf.DUMMYFUNCTION("""COMPUTED_VALUE"""),146.53) -> 146.53 | G21: =IFERROR(__xludf.DUMMYFUNCTION("""COMPUTED_VALUE"""),25418.9) -> 25418.9
A22: =IFERROR(__xludf.DUMMYFUNCTION("""COMPUTED_VALUE"""),46052.64583333333) -> 46052.646 | B22: =IFERROR(__xludf.DUMMYFUNCTION("""COMPUTED_VALUE"""),268.96) -> 268.96 | C22: =IFERROR(__xludf.DUMMYFUNCTION("""COMPUTED_VALUE"""),4619.4) -> 4619.4 | D22: =IFERROR(__xludf.DUMMYFUNCTION("""COMPUTED_VALUE"""),3123.9) -> 3123.9 | E22: =IFERROR(__xludf.DUMMYFUNCTION("""COMPUTED_VALUE"""),364.5) -> 364.5 | F22: =IFERROR(__xludf.DUMMYFUNCTION("""COMPUTED_VALUE"""),131.12) -> 131.12 | G22: =IFERROR(__xludf.DUMMYFUNCTION("""COMPUTED_VALUE"""),25320.65) -> 25320.65
A23: =IFERROR(__xludf.DUMMYFUNCTION("""COMPUTED_VALUE"""),46055.64583333333) -> 46055.646 | B23: =IFERROR(__xludf.DUMMYFUNCTION("""COMPUTED_VALUE"""),253.95) -> 253.95 | C23: =IFERROR(__xludf.DUMMYFUNCTION("""COMPUTED_VALUE"""),4338.7) -> 4338.7 | D23: =IFERROR(__xludf.DUMMYFUNCTION("""COMPUTED_VALUE"""),3169.6) -> 3169.6 | E23: =IFERROR(__xludf.DUMMYFUNCTION("""COMPUTED_VALUE"""),366.7) -> 366.7 | F23: =IFERROR(__xludf.DUMMYFUNCTION("""COMPUTED_VALUE"""),118.67) -> 118.67 | G23: =IFERROR(__xludf.DUMMYFUNCTION("""COMPUTED_VALUE"""),25088.4) -> 25088.4
A24: =IFERROR(__xludf.DUMMYFUNCTION("""COMPUTED_VALUE"""),46056.64583333333) -> 46056.646 | B24: =IFERROR(__xludf.DUMMYFUNCTION("""COMPUTED_VALUE"""),257.0) -> 257 | C24: =IFERROR(__xludf.DUMMYFUNCTION("""COMPUTED_VALUE"""),4470.4) -> 4470.4 | D24: =IFERROR(__xludf.DUMMYFUNCTION("""COMPUTED_VALUE"""),3225.3) -> 3225.3 | E24: =IFERROR(__xludf.DUMMYFUNCTION("""COMPUTED_VALUE"""),373.45) -> 373.45 | F24: =IFERROR(__xludf.DUMMYFUNCTION("""COMPUTED_VALUE"""),125.2) -> 125.2 | G24: =IFERROR(__xludf.DUMMYFUNCTION("""COMPUTED_VALUE"""),25727.55) -> 25727.55
A25: =IFERROR(__xludf.DUMMYFUNCTION("""COMPUTED_VALUE"""),46057.64583333333) -> 46057.646 | B25: =IFERROR(__xludf.DUMMYFUNCTION("""COMPUTED_VALUE"""),266.95) -> 266.95 | C25: =IFERROR(__xludf.DUMMYFUNCTION("""COMPUTED_VALUE"""),4217.1) -> 4217.1 | D25: =IFERROR(__xludf.DUMMYFUNCTION("""COMPUTED_VALUE"""),2999.1) -> 2999.1 | E25: =IFERROR(__xludf.DUMMYFUNCTION("""COMPUTED_VALUE"""),382.45) -> 382.45 | F25: =IFERROR(__xludf.DUMMYFUNCTION("""COMPUTED_VALUE"""),129.6) -> 129.6 | G25: =IFERROR(__xludf.DUMMYFUNCTION("""COMPUTED_VALUE"""),25776.0) -> 25776
A26: =IFERROR(__xludf.DUMMYFUNCTION("""COMPUTED_VALUE"""),46058.64583333333) -> 46058.646 | B26: =IFERROR(__xludf.DUMMYFUNCTION("""COMPUTED_VALUE"""),269.2) -> 269.2 | C26: =IFERROR(__xludf.DUMMYFUNCTION("""COMPUTED_VALUE"""),4035.5) -> 4035.5 | D26: =IFERROR(__xludf.DUMMYFUNCTION("""COMPUTED_VALUE"""),2991.5) -> 2991.5 | E26: =IFERROR(__xludf.DUMMYFUNCTION("""COMPUTED_VALUE"""),382.05) -> 382.05 | F26: =IFERROR(__xludf.DUMMYFUNCTION("""COMPUTED_VALUE"""),125.22) -> 125.22 | G26: =IFERROR(__xludf.DUMMYFUNCTION("""COMPUTED_VALUE"""),25642.8) -> 25642.8
A27: =IFERROR(__xludf.DUMMYFUNCTION("""COMPUTED_VALUE"""),46059.64583333333) -> 46059.646 | B27: =IFERROR(__xludf.DUMMYFUNCTION("""COMPUTED_VALUE"""),268.95) -> 268.95 | C27: =IFERROR(__xludf.DUMMYFUNCTION("""COMPUTED_VALUE"""),4067.5) -> 4067.5 | D27: =IFERROR(__xludf.DUMMYFUNCTION("""COMPUTED_VALUE"""),2941.6) -> 2941.6 | E27: =IFERROR(__xludf.DUMMYFUNCTION("""COMPUTED_VALUE"""),386.35) -> 386.35 | F27: =IFERROR(__xludf.DUMMYFUNCTION("""COMPUTED_VALUE"""),125.04) -> 125.04 | G27: =IFERROR(__xludf.DUMMYFUNCTION("""COMPUTED_VALUE"""),25693.7) -> 25693.7
A28: =IFERROR(__xludf.DUMMYFUNCTION("""COMPUTED_VALUE"""),46062.64583333333) -> 46062.646 | B28: =IFERROR(__xludf.DUMMYFUNCTION("""COMPUTED_VALUE"""),266.6) -> 266.6 | C28: =IFERROR(__xludf.DUMMYFUNCTION("""COMPUTED_VALUE"""),4131.0) -> 4131 | D28: =IFERROR(__xludf.DUMMYFUNCTION("""COMPUTED_VALUE"""),2948.2) -> 2948.2 | E28: =IFERROR(__xludf.DUMMYFUNCTION("""COMPUTED_VALUE"""),388.3) -> 388.3 | F28: =IFERROR(__xludf.DUMMYFUNCTION("""COMPUTED_VALUE"""),127.98) -> 127.98 | G28: =IFERROR(__xludf.DUMMYFUNCTION("""COMPUTED_VALUE"""),25867.3) -> 25867.3
A29: =IFERROR(__xludf.DUMMYFUNCTION("""COMPUTED_VALUE"""),46063.64583333333) -> 46063.646 | B29: =IFERROR(__xludf.DUMMYFUNCTION("""COMPUTED_VALUE"""),272.15) -> 272.15 | C29: =IFERROR(__xludf.DUMMYFUNCTION("""COMPUTED_VALUE"""),4168.3) -> 4168.3 | D29: =IFERROR(__xludf.DUMMYFUNCTION("""COMPUTED_VALUE"""),2984.6) -> 2984.6 | E29: =IFERROR(__xludf.DUMMYFUNCTION("""COMPUTED_VALUE"""),386.35) -> 386.35 | F29: =IFERROR(__xludf.DUMMYFUNCTION("""COMPUTED_VALUE"""),128.34) -> 128.34 | G29: =IFERROR(__xludf.DUMMYFUNCTION("""COMPUTED_VALUE"""),25935.15) -> 25935.15
A30: =IFERROR(__xludf.DUMMYFUNCTION("""COMPUTED_VALUE"""),46064.64583333333) -> 46064.646 | B30: =IFERROR(__xludf.DUMMYFUNCTION("""COMPUTED_VALUE"""),274.6) -> 274.6 | C30: =IFERROR(__xludf.DUMMYFUNCTION("""COMPUTED_VALUE"""),4133.0) -> 4133 | D30: =IFERROR(__xludf.DUMMYFUNCTION("""COMPUTED_VALUE"""),2909.8) -> 2909.8 | E30: =IFERROR(__xludf.DUMMYFUNCTION("""COMPUTED_VALUE"""),387.6) -> 387.6 | F30: =IFERROR(__xludf.DUMMYFUNCTION("""COMPUTED_VALUE"""),128.7) -> 128.7 | G30: =IFERROR(__xludf.DUMMYFUNCTION("""COMPUTED_VALUE"""),25953.85) -> 25953.85
A31: =IFERROR(__xludf.DUMMYFUNCTION("""COMPUTED_VALUE"""),46065.64583333333) -> 46065.646 | B31: =IFERROR(__xludf.DUMMYFUNCTION("""COMPUTED_VALUE"""),276.35) -> 276.35 | C31: =IFERROR(__xludf.DUMMYFUNCTION("""COMPUTED_VALUE"""),4158.9) -> 4158.9 | D31: =IFERROR(__xludf.DUMMYFUNCTION("""COMPUTED_VALUE"""),2750.1) -> 2750.1 | E31: =IFERROR(__xludf.DUMMYFUNCTION("""COMPUTED_VALUE"""),377.7) -> 377.7 | F31: =IFERROR(__xludf.DUMMYFUNCTION("""COMPUTED_VALUE"""),128.52) -> 128.52 | G31: =IFERROR(__xludf.DUMMYFUNCTION("""COMPUTED_VALUE"""),25807.2) -> 25807.2
A32: =IFERROR(__xludf.DUMMYFUNCTION("""COMPUTED_VALUE"""),46066.64583333333) -> 46066.646 | B32: =IFERROR(__xludf.DUMMYFUNCTION("""COMPUTED_VALUE"""),267.4) -> 267.4 | C32: =IFERROR(__xludf.DUMMYFUNCTION("""COMPUTED_VALUE"""),4212.4) -> 4212.4 | D32: =IFERROR(__xludf.DUMMYFUNCTION("""COMPUTED_VALUE"""),2692.2) -> 2692.2 | E32: =IFERROR(__xludf.DUMMYFUNCTION("""COMPUTED_VALUE"""),374.1) -> 374.1 | F32: =IFERROR(__xludf.DUMMYFUNCTION("""COMPUTED_VALUE"""),126.1) -> 126.1 | G32: =IFERROR(__xludf.DUMMYFUNCTION("""COMPUTED_VALUE"""),25471.1) -> 25471.1
A33: =IFERROR(__xludf.DUMMYFUNCTION("""COMPUTED_VALUE"""),46069.64583333333) -> 46069.646 | B33: =IFERROR(__xludf.DUMMYFUNCTION("""COMPUTED_VALUE"""),271.55) -> 271.55 | C33: =IFERROR(__xludf.DUMMYFUNCTION("""COMPUTED_VALUE"""),4226.1) -> 4226.1 | D33: =IFERROR(__xludf.DUMMYFUNCTION("""COMPUTED_VALUE"""),2706.6) -> 2706.6 | E33: =IFERROR(__xludf.DUMMYFUNCTION("""COMPUTED_VALUE"""),374.35) -> 374.35 | F33: =IFERROR(__xludf.DUMMYFUNCTION("""COMPUTED_VALUE"""),126.92) -> 126.92 | G33: =IFERROR(__xludf.DUMMYFUNCTION("""COMPUTED_VALUE"""),25682.75) -> 25682.75
A34: =IFERROR(__xludf.DUMMYFUNCTION("""COMPUTED_VALUE"""),46070.64583333333) -> 46070.646 | B34: =IFERROR(__xludf.DUMMYFUNCTION("""COMPUTED_VALUE"""),271.85) -> 271.85 | C34: =IFERROR(__xludf.DUMMYFUNCTION("""COMPUTED_VALUE"""),4247.6) -> 4247.6 | D34: =IFERROR(__xludf.DUMMYFUNCTION("""COMPUTED_VALUE"""),2717.4) -> 2717.4 | E34: =IFERROR(__xludf.DUMMYFUNCTION("""COMPUTED_VALUE"""),374.95) -> 374.95 | F34: =IFERROR(__xludf.DUMMYFUNCTION("""COMPUTED_VALUE"""),124.58) -> 124.58 | G34: =IFERROR(__xludf.DUMMYFUNCTION("""COMPUTED_VALUE"""),25725.4) -> 25725.4
A35: =IFERROR(__xludf.DUMMYFUNCTION("""COMPUTED_VALUE"""),46071.64583333333) -> 46071.646 | B35: =IFERROR(__xludf.DUMMYFUNCTION("""COMPUTED_VALUE"""),264.6) -> 264.6 | C35: =IFERROR(__xludf.DUMMYFUNCTION("""COMPUTED_VALUE"""),4251.1) -> 4251.1 | D35: =IFERROR(__xludf.DUMMYFUNCTION("""COMPUTED_VALUE"""),2694.9) -> 2694.9 | E35: =IFERROR(__xludf.DUMMYFUNCTION("""COMPUTED_VALUE"""),380.9) -> 380.9 | F35: =IFERROR(__xludf.DUMMYFUNCTION("""COMPUTED_VALUE"""),124.64) -> 124.64 | G35: =IFERROR(__xludf.DUMMYFUNCTION("""COMPUTED_VALUE"""),25819.35) -> 25819.35
A36: =IFERROR(__xludf.DUMMYFUNCTION("""COMPUTED_VALUE"""),46072.64583333333) -> 46072.646 | B36: =IFERROR(__xludf.DUMMYFUNCTION("""COMPUTED_VALUE"""),274.65) -> 274.65 | C36: =IFERROR(__xludf.DUMMYFUNCTION("""COMPUTED_VALUE"""),4132.6) -> 4132.6 | D36: =IFERROR(__xludf.DUMMYFUNCTION("""COMPUTED_VALUE"""),2677.9) -> 2677.9 | E36: =IFERROR(__xludf.DUMMYFUNCTION("""COMPUTED_VALUE"""),367.65) -> 367.65 | F36: =IFERROR(__xludf.DUMMYFUNCTION("""COMPUTED_VALUE"""),127.09) -> 127.09 | G36: =IFERROR(__xludf.DUMMYFUNCTION("""COMPUTED_VALUE"""),25454.35) -> 25454.35
A37: =IFERROR(__xludf.DUMMYFUNCTION("""COMPUTED_VALUE"""),46073.64583333333) -> 46073.646 | B37: =IFERROR(__xludf.DUMMYFUNCTION("""COMPUTED_VALUE"""),278.65) -> 278.65 | C37: =IFERROR(__xludf.DUMMYFUNCTION("""COMPUTED_VALUE"""),4170.0) -> 4170 | D37: =IFERROR(__xludf.DUMMYFUNCTION("""COMPUTED_VALUE"""),2686.2) -> 2686.2 | E37: =IFERROR(__xludf.DUMMYFUNCTION("""COMPUTED_VALUE"""),366.3) -> 366.3 | F37: =IFERROR(__xludf.DUMMYFUNCTION("""COMPUTED_VALUE"""),127.54) -> 127.54 | G37: =IFERROR(__xludf.DUMMYFUNCTION("""COMPUTED_VALUE"""),25571.25) -> 25571.25
A38: =IFERROR(__xludf.DUMMYFUNCTION("""COMPUTED_VALUE"""),46076.64583333333) -> 46076.646 | B38: =IFERROR(__xludf.DUMMYFUNCTION("""COMPUTED_VALUE"""),275.65) -> 275.65 | C38: =IFERROR(__xludf.DUMMYFUNCTION("""COMPUTED_VALUE"""),4025.4) -> 4025.4 | D38: =IFERROR(__xludf.DUMMYFUNCTION("""COMPUTED_VALUE"""),2676.3) -> 2676.3 | E38: =IFERROR(__xludf.DUMMYFUNCTION("""COMPUTED_VALUE"""),372.1) -> 372.1 | F38: =IFERROR(__xludf.DUMMYFUNCTION("""COMPUTED_VALUE"""),130.0) -> 130 | G38: =IFERROR(__xludf.DUMMYFUNCTION("""COMPUTED_VALUE"""),25713.0) -> 25713
A39: =IFERROR(__xludf.DUMMYFUNCTION("""COMPUTED_VALUE"""),46077.64583333333) -> 46077.646 | B39: =IFERROR(__xludf.DUMMYFUNCTION("""COMPUTED_VALUE"""),276.5) -> 276.5 | C39: =IFERROR(__xludf.DUMMYFUNCTION("""COMPUTED_VALUE"""),3952.6) -> 3952.6 | D39: =IFERROR(__xludf.DUMMYFUNCTION("""COMPUTED_VALUE"""),2573.7) -> 2573.7 | E39: =IFERROR(__xludf.DUMMYFUNCTION("""COMPUTED_VALUE"""),374.45) -> 374.45 | F39: =IFERROR(__xludf.DUMMYFUNCTION("""COMPUTED_VALUE"""),131.22) -> 131.22 | G39: =IFERROR(__xludf.DUMMYFUNCTION("""COMPUTED_VALUE"""),25424.65) -> 25424.65
A40: =IFERROR(__xludf.DUMMYFUNCTION("""COMPUTED_VALUE"""),46078.64583333333) -> 46078.646 | B40: =IFERROR(__xludf.DUMMYFUNCTION("""COMPUTED_VALUE"""),277.45) -> 277.45 | C40: =IFERROR(__xludf.DUMMYFUNCTION("""COMPUTED_VALUE"""),3985.0) -> 3985 | D40: =IFERROR(__xludf.DUMMYFUNCTION("""COMPUTED_VALUE"""),2629.3) -> 2629.3 | E40: =IFERROR(__xludf.DUMMYFUNCTION("""COMPUTED_VALUE"""),381.05) -> 381.05 | F40: =IFERROR(__xludf.DUMMYFUNCTION("""COMPUTED_VALUE"""),131.69) -> 131.69 | G40: =IFERROR(__xludf.DUMMYFUNCTION("""COMPUTED_VALUE"""),25482.5) -> 25482.5
...

Sheet Events
A1: Events | B1: Date
A2: War begins | B2: 46081
A3: Ceasefire announced | B3: 46120
A4: Brent $111 / rupee record low | B4: 46142
A5: Renewed US strikes | B5: 46211
A6: Sensex 2026 low | B6: 46296

Sheet Macro
A1: USD/INR
A2: =IFERROR(__xludf.DUMMYFUNCTION("GOOGLEFINANCE(""CURRENCY:USDINR"",""price"",DATE(2026,1,1),TODAY(),""DAILY"")"),"Date") -> Date | B2: =IFERROR(__xludf.DUMMYFUNCTION("""COMPUTED_VALUE"""),"Close") -> Close
A3: =IFERROR(__xludf.DUMMYFUNCTION("""COMPUTED_VALUE"""),46023.99861111111) -> 46023.999 | B3: =IFERROR(__xludf.DUMMYFUNCTION("""COMPUTED_VALUE"""),89.9619) -> 89.9619
A4: =IFERROR(__xludf.DUMMYFUNCTION("""COMPUTED_VALUE"""),46024.99861111111) -> 46024.999 | B4: =IFERROR(__xludf.DUMMYFUNCTION("""COMPUTED_VALUE"""),90.0142) -> 90.0142
A5: =IFERROR(__xludf.DUMMYFUNCTION("""COMPUTED_VALUE"""),46025.99861111111) -> 46025.999 | B5: =IFERROR(__xludf.DUMMYFUNCTION("""COMPUTED_VALUE"""),90.0132) -> 90.0132
A6: =IFERROR(__xludf.DUMMYFUNCTION("""COMPUTED_VALUE"""),46026.99861111111) -> 46026.999 | B6: =IFERROR(__xludf.DUMMYFUNCTION("""COMPUTED_VALUE"""),90.007) -> 90.007
A7: =IFERROR(__xludf.DUMMYFUNCTION("""COMPUTED_VALUE"""),46027.99861111111) -> 46027.999 | B7: =IFERROR(__xludf.DUMMYFUNCTION("""COMPUTED_VALUE"""),90.233) -> 90.233
A8: =IFERROR(__xludf.DUMMYFUNCTION("""COMPUTED_VALUE"""),46028.99861111111) -> 46028.999 | B8: =IFERROR(__xludf.DUMMYFUNCTION("""COMPUTED_VALUE"""),90.1661) -> 90.1661
A9: =IFERROR(__xludf.DUMMYFUNCTION("""COMPUTED_VALUE"""),46029.99861111111) -> 46029.999 | B9: =IFERROR(__xludf.DUMMYFUNCTION("""COMPUTED_VALUE"""),89.8644) -> 89.8644
A10: =IFERROR(__xludf.DUMMYFUNCTION("""COMPUTED_VALUE"""),46030.99861111111) -> 46030.999 | B10: =IFERROR(__xludf.DUMMYFUNCTION("""COMPUTED_VALUE"""),89.9054) -> 89.9054
A11: =IFERROR(__xludf.DUMMYFUNCTION("""COMPUTED_VALUE"""),46031.99861111111) -> 46031.999 | B11: =IFERROR(__xludf.DUMMYFUNCTION("""COMPUTED_VALUE"""),90.2681) -> 90.2681
A12: =IFERROR(__xludf.DUMMYFUNCTION("""COMPUTED_VALUE"""),46032.99861111111) -> 46032.999 | B12: =IFERROR(__xludf.DUMMYFUNCTION("""COMPUTED_VALUE"""),90.2681) -> 90.2681
A13: =IFERROR(__xludf.DUMMYFUNCTION("""COMPUTED_VALUE"""),46033.99861111111) -> 46033.999 | B13: =IFERROR(__xludf.DUMMYFUNCTION("""COMPUTED_VALUE"""),90.236) -> 90.236
A14: =IFERROR(__xludf.DUMMYFUNCTION("""COMPUTED_VALUE"""),46034.99861111111) -> 46034.999 | B14: =IFERROR(__xludf.DUMMYFUNCTION("""COMPUTED_VALUE"""),90.1327) -> 90.1327
A15: =IFERROR(__xludf.DUMMYFUNCTION("""COMPUTED_VALUE"""),46035.99861111111) -> 46035.999 | B15: =IFERROR(__xludf.DUMMYFUNCTION("""COMPUTED_VALUE"""),90.273) -> 90.273
A16: =IFERROR(__xludf.DUMMYFUNCTION("""COMPUTED_VALUE"""),46036.99861111111) -> 46036.999 | B16: =IFERROR(__xludf.DUMMYFUNCTION("""COMPUTED_VALUE"""),90.1832) -> 90.1832
A17: =IFERROR(__xludf.DUMMYFUNCTION("""COMPUTED_VALUE"""),46037.99861111111) -> 46037.999 | B17: =IFERROR(__xludf.DUMMYFUNCTION("""COMPUTED_VALUE"""),90.3616) -> 90.3616
A18: =IFERROR(__xludf.DUMMYFUNCTION("""COMPUTED_VALUE"""),46038.99861111111) -> 46038.999 | B18: =IFERROR(__xludf.DUMMYFUNCTION("""COMPUTED_VALUE"""),90.5364) -> 90.5364
A19: =IFERROR(__xludf.DUMMYFUNCTION("""COMPUTED_VALUE"""),46039.99861111111) -> 46039.999 | B19: =IFERROR(__xludf.DUMMYFUNCTION("""COMPUTED_VALUE"""),90.7944) -> 90.7944
A20: =IFERROR(__xludf.DUMMYFUNCTION("""COMPUTED_VALUE"""),46040.99861111111) -> 46040.999 | B20: =IFERROR(__xludf.DUMMYFUNCTION("""COMPUTED_VALUE"""),90.702) -> 90.702
A21: =IFERROR(__xludf.DUMMYFUNCTION("""COMPUTED_VALUE"""),46041.99861111111) -> 46041.999 | B21: =IFERROR(__xludf.DUMMYFUNCTION("""COMPUTED_VALUE"""),90.9045) -> 90.9045
A22: =IFERROR(__xludf.DUMMYFUNCTION("""COMPUTED_VALUE"""),46042.99861111111) -> 46042.999 | B22: =IFERROR(__xludf.DUMMYFUNCTION("""COMPUTED_VALUE"""),91.1184) -> 91.1184
A23: =IFERROR(__xludf.DUMMYFUNCTION("""COMPUTED_VALUE"""),46043.99861111111) -> 46043.999 | B23: =IFERROR(__xludf.DUMMYFUNCTION("""COMPUTED_VALUE"""),91.5369) -> 91.5369
A24: =IFERROR(__xludf.DUMMYFUNCTION("""COMPUTED_VALUE"""),46044.99861111111) -> 46044.999 | B24: =IFERROR(__xludf.DUMMYFUNCTION("""COMPUTED_VALUE"""),91.5583) -> 91.5583
A25: =IFERROR(__xludf.DUMMYFUNCTION("""COMPUTED_VALUE"""),46045.99861111111) -> 46045.999 | B25: =IFERROR(__xludf.DUMMYFUNCTION("""COMPUTED_VALUE"""),91.467) -> 91.467
A26: =IFERROR(__xludf.DUMMYFUNCTION("""COMPUTED_VALUE"""),46046.99861111111) -> 46046.999 | B26: =IFERROR(__xludf.DUMMYFUNCTION("""COMPUTED_VALUE"""),91.501) -> 91.501
A27: =IFERROR(__xludf.DUMMYFUNCTION("""COMPUTED_VALUE"""),46047.99861111111) -> 46047.999 | B27: =IFERROR(__xludf.DUMMYFUNCTION("""COMPUTED_VALUE"""),91.501) -> 91.501
A28: =IFERROR(__xludf.DUMMYFUNCTION("""COMPUTED_VALUE"""),46048.99861111111) -> 46048.999 | B28: =IFERROR(__xludf.DUMMYFUNCTION("""COMPUTED_VALUE"""),91.7131) -> 91.7131
A29: =IFERROR(__xludf.DUMMYFUNCTION("""COMPUTED_VALUE"""),46049.99861111111) -> 46049.999 | B29: =IFERROR(__xludf.DUMMYFUNCTION("""COMPUTED_VALUE"""),91.5343) -> 91.5343
A30: =IFERROR(__xludf.DUMMYFUNCTION("""COMPUTED_VALUE"""),46050.99861111111) -> 46050.999 | B30: =IFERROR(__xludf.DUMMYFUNCTION("""COMPUTED_VALUE"""),92.0408) -> 92.0408
A31: =IFERROR(__xludf.DUMMYFUNCTION("""COMPUTED_VALUE"""),46051.99861111111) -> 46051.999 | B31: =IFERROR(__xludf.DUMMYFUNCTION("""COMPUTED_VALUE"""),91.7819) -> 91.7819
A32: =IFERROR(__xludf.DUMMYFUNCTION("""COMPUTED_VALUE"""),46052.99861111111) -> 46052.999 | B32: =IFERROR(__xludf.DUMMYFUNCTION("""COMPUTED_VALUE"""),91.6823) -> 91.6823
A33: =IFERROR(__xludf.DUMMYFUNCTION("""COMPUTED_VALUE"""),46053.99861111111) -> 46053.999 | B33: =IFERROR(__xludf.DUMMYFUNCTION("""COMPUTED_VALUE"""),91.6823) -> 91.6823
A34: =IFERROR(__xludf.DUMMYFUNCTION("""COMPUTED_VALUE"""),46054.99861111111) -> 46054.999 | B34: =IFERROR(__xludf.DUMMYFUNCTION("""COMPUTED_VALUE"""),91.687) -> 91.687
A35: =IFERROR(__xludf.DUMMYFUNCTION("""COMPUTED_VALUE"""),46055.99861111111) -> 46055.999 | B35: =IFERROR(__xludf.DUMMYFUNCTION("""COMPUTED_VALUE"""),90.2456) -> 90.2456
A36: =IFERROR(__xludf.DUMMYFUNCTION("""COMPUTED_VALUE"""),46056.99861111111) -> 46056.999 | B36: =IFERROR(__xludf.DUMMYFUNCTION("""COMPUTED_VALUE"""),90.4229) -> 90.4229
A37: =IFERROR(__xludf.DUMMYFUNCTION("""COMPUTED_VALUE"""),46057.99861111111) -> 46057.999 | B37: =IFERROR(__xludf.DUMMYFUNCTION("""COMPUTED_VALUE"""),90.125) -> 90.125
A38: =IFERROR(__xludf.DUMMYFUNCTION("""COMPUTED_VALUE"""),46058.99861111111) -> 46058.999 | B38: =IFERROR(__xludf.DUMMYFUNCTION("""COMPUTED_VALUE"""),90.3148) -> 90.3148
A39: =IFERROR(__xludf.DUMMYFUNCTION("""COMPUTED_VALUE"""),46059.99861111111) -> 46059.999 | B39: =IFERROR(__xludf.DUMMYFUNCTION("""COMPUTED_VALUE"""),90.588) -> 90.588
A40: =IFERROR(__xludf.DUMMYFUNCTION("""COMPUTED_VALUE"""),46060.99861111111) -> 46060.999 | B40: =IFERROR(__xludf.DUMMYFUNCTION("""COMPUTED_VALUE"""),90.588) -> 90.588
...

Sheet Summary
B1: =Prices!B1 -> ONGC | C1: =Prices!C1 -> HAL | D1: =Prices!D1 -> TCS | E1: =Prices!E1 -> BPCL | F1: =Prices!F1 -> GOLDBEES | G1: =Prices!G1 -> NIFTY | H1: USD/INR
A2: =Events!A2 -> War begins | B2: {=LET(m, MATCH(Events!$B2, Prices!$A$3:$A$300, 1), later, INDEX(Prices!B$3:B$300, m+5), IF(later="", "", later / INDEX(Prices!B$3:B$300, m) - 1))} -> -0.031819807 | C2: {=LET(m, MATCH(Events!$B2, Prices!$A$3:$A$300, 1), later, INDEX(Prices!C$3:C$300, m+5), IF(later="", "", later / INDEX(Prices!C$3:C$300, m) - 1))} -> 0.019600327 | D2: {=LET(m, MATCH(Events!$B2, Prices!$A$3:$A$300, 1), later, INDEX(Prices!D$3:D$300, m+5), IF(later="", "", later / INDEX(Prices!D$3:D$300, m) - 1))} -> -0.041707742 | E2: {=LET(m, MATCH(Events!$B2, Prices!$A$3:$A$300, 1), later, INDEX(Prices!E$3:E$300, m+5), IF(later="", "", later / INDEX(Prices!E$3:E$300, m) - 1))} -> -0.14076284 | F2: {=LET(m, MATCH(Events!$B2, Prices!$A$3:$A$300, 1), later, INDEX(Prices!F$3:F$300, m+5), IF(later="", "", later / INDEX(Prices!F$3:F$300, m) - 1))} -> -0.001899696 | G2: {=LET(m, MATCH(Events!$B2, Prices!$A$3:$A$300, 1), later, INDEX(Prices!G$3:G$300, m+5), IF(later="", "", later / INDEX(Prices!G$3:G$300, m) - 1))} -> -0.045697446 | H2: =LET(d, Events!$B2, base, LOOKUP(d, Macro!$A$3:$A$301, Macro!$B$3:$B$301), later, LOOKUP(d+7, Macro!$A$3:$A$301, Macro!$B$3:$B$301), IF(d+7>MAX(Macro!$A$3:$A$301), "", later/base-1)) -> 0.0094377947
A3: =Events!A3 -> Ceasefire announced | B3: {=LET(m, MATCH(Events!$B3, Prices!$A$3:$A$300, 1), later, INDEX(Prices!B$3:B$300, m+5), IF(later="", "", later / INDEX(Prices!B$3:B$300, m) - 1))} -> 0.0033141462 | C3: {=LET(m, MATCH(Events!$B3, Prices!$A$3:$A$300, 1), later, INDEX(Prices!C$3:C$300, m+5), IF(later="", "", later / INDEX(Prices!C$3:C$300, m) - 1))} -> 0.11669564 | D3: {=LET(m, MATCH(Events!$B3, Prices!$A$3:$A$300, 1), later, INDEX(Prices!D$3:D$300, m+5), IF(later="", "", later / INDEX(Prices!D$3:D$300, m) - 1))} -> 0.00594535 | E3: {=LET(m, MATCH(Events!$B3, Prices!$A$3:$A$300, 1), later, INDEX(Prices!E$3:E$300, m+5), IF(later="", "", later / INDEX(Prices!E$3:E$300, m) - 1))} -> 0.11894035 | F3: {=LET(m, MATCH(Events!$B3, Prices!$A$3:$A$300, 1), later, INDEX(Prices!F$3:F$300, m+5), IF(later="", "", later / INDEX(Prices!F$3:F$300, m) - 1))} -> 0.026933815 | G3: {=LET(m, MATCH(Events!$B3, Prices!$A$3:$A$300, 1), later, INDEX(Prices!G$3:G$300, m+5), IF(later="", "", later / INDEX(Prices!G$3:G$300, m) - 1))} -> 0.047901175 | H3: =LET(d, Events!$B3, base, LOOKUP(d, Macro!$A$3:$A$301, Macro!$B$3:$B$301), later, LOOKUP(d+7, Macro!$A$3:$A$301, Macro!$B$3:$B$301), IF(d+7>MAX(Macro!$A$3:$A$301), "", later/base-1)) -> 0.003286661
A4: =Events!A4 -> Brent $111 / rupee record low | B4: {=LET(m, MATCH(Events!$B4, Prices!$A$3:$A$300, 1), later, INDEX(Prices!B$3:B$300, m+5), IF(later="", "", later / INDEX(Prices!B$3:B$300, m) - 1))} -> -0.058062376 | C4: {=LET(m, MATCH(Events!$B4, Prices!$A$3:$A$300, 1), later, INDEX(Prices!C$3:C$300, m+5), IF(later="", "", later / INDEX(Prices!C$3:C$300, m) - 1))} -> 0.09892913 | D4: {=LET(m, MATCH(Events!$B4, Prices!$A$3:$A$300, 1), later, INDEX(Prices!D$3:D$300, m+5), IF(later="", "", later / INDEX(Prices!D$3:D$300, m) - 1))} -> -0.029619752 | E4: {=LET(m, MATCH(Events!$B4, Prices!$A$3:$A$300, 1), later, INDEX(Prices!E$3:E$300, m+5), IF(later="", "", later / INDEX(Prices!E$3:E$300, m) - 1))} -> 0.012175058 | F4: {=LET(m, MATCH(Events!$B4, Prices!$A$3:$A$300, 1), later, INDEX(Prices!F$3:F$300, m+5), IF(later="", "", later / INDEX(Prices!F$3:F$300, m) - 1))} -> 0.023770357 | G4: {=LET(m, MATCH(Events!$B4, Prices!$A$3:$A$300, 1), later, INDEX(Prices!G$3:G$300, m+5), IF(later="", "", later / INDEX(Prices!G$3:G$300, m) - 1))} -> 0.0061627164 | H4: =LET(d, Events!$B4, base, LOOKUP(d, Macro!$A$3:$A$301, Macro!$B$3:$B$301), later, LOOKUP(d+7, Macro!$A$3:$A$301, Macro!$B$3:$B$301), IF(d+7>MAX(Macro!$A$3:$A$301), "", later/base-1)) -> -0.0032512753
A5: =Events!A5 -> Renewed US strikes | B5: {=LET(m, MATCH(Events!$B5, Prices!$A$3:$A$300, 1), later, INDEX(Prices!B$3:B$300, m+5), IF(later="", "", later / INDEX(Prices!B$3:B$300, m) - 1))} -> 0.019330002 | C5: {=LET(m, MATCH(Events!$B5, Prices!$A$3:$A$300, 1), later, INDEX(Prices!C$3:C$300, m+5), IF(later="", "", later / INDEX(Prices!C$3:C$300, m) - 1))} -> 0.0095675295 | D5: {=LET(m, MATCH(Events!$B5, Prices!$A$3:$A$300, 1), later, INDEX(Prices!D$3:D$300, m+5), IF(later="", "", later / INDEX(Prices!D$3:D$300, m) - 1))} -> 0.049854492 | E5: {=LET(m, MATCH(Events!$B5, Prices!$A$3:$A$300, 1), later, INDEX(Prices!E$3:E$300, m+5), IF(later="", "", later / INDEX(Prices!E$3:E$300, m) - 1))} -> -0.027392897 | F5: {=LET(m, MATCH(Events!$B5, Prices!$A$3:$A$300, 1), later, INDEX(Prices!F$3:F$300, m+5), IF(later="", "", later / INDEX(Prices!F$3:F$300, m) - 1))} -> -0.021926126 | G5: {=LET(m, MATCH(Events!$B5, Prices!$A$3:$A$300, 1), later, INDEX(Prices!G$3:G$300, m+5), IF(later="", "", later / INDEX(Prices!G$3:G$300, m) - 1))} -> -0.014207724 | H5: =LET(d, Events!$B5, base, LOOKUP(d, Macro!$A$3:$A$301, Macro!$B$3:$B$301), later, LOOKUP(d+7, Macro!$A$3:$A$301, Macro!$B$3:$B$301), IF(d+7>MAX(Macro!$A$3:$A$301), "", later/base-1)) -> 0.0087024836
A6: =Events!A6 -> Sensex 2026 low | B6: {=LET(m, MATCH(Events!$B6, Prices!$A$3:$A$300, 1), later, INDEX(Prices!B$3:B$300, m+1), IF(later="", "", later / INDEX(Prices!B$3:B$300, m) - 1))} -> -0.015190434 | C6: {=LET(m, MATCH(Events!$B6, Prices!$A$3:$A$300, 1), later, INDEX(Prices!C$3:C$300, m+1), IF(later="", "", later / INDEX(Prices!C$3:C$300, m) - 1))} -> -0.014353042 | D6: {=LET(m, MATCH(Events!$B6, Prices!$A$3:$A$300, 1), later, INDEX(Prices!D$3:D$300, m+1), IF(later="", "", later / INDEX(Prices!D$3:D$300, m) - 1))} -> 0.011898956 | E6: {=LET(m, MATCH(Events!$B6, Prices!$A$3:$A$300, 1), later, INDEX(Prices!E$3:E$300, m+1), IF(later="", "", later / INDEX(Prices!E$3:E$300, m) - 1))} -> -0.0085751979 | F6: {=LET(m, MATCH(Events!$B6, Prices!$A$3:$A$300, 1), later, INDEX(Prices!F$3:F$300, m+1), IF(later="", "", later / INDEX(Prices!F$3:F$300, m) - 1))} -> -0.0013158977 | G6: {=LET(m, MATCH(Events!$B6, Prices!$A$3:$A$300, 1), later, INDEX(Prices!G$3:G$300, m+1), IF(later="", "", later / INDEX(Prices!G$3:G$300, m) - 1))} -> -0.0087752454 | H6: =LET(d, Events!$B6, base, LOOKUP(d, Macro!$A$3:$A$301, Macro!$B$3:$B$301), later, LOOKUP(d+1, Macro!$A$3:$A$301, Macro!$B$3:$B$301), IF(d+1>MAX(Macro!$A$3:$A$301), "", later/base-1)) -> 0.0031033983
A8: AVERAGE | B8: =AVERAGE(B2:B5) -> -0.016809508 | C8: =AVERAGE(C2:C5) -> 0.061198157 | D8: =AVERAGE(D2:D5) -> -0.0038819132 | E8: =AVERAGE(E2:E5) -> -0.0092600834 | F8: =AVERAGE(F2:F5) -> 0.0067195875 | G8: =AVERAGE(G2:G5) -> -0.0014603198 | H8: =AVERAGE(H2:H5) -> 0.004543916

Sheet Abnormal
B1: ONGC | C1: HAL | D1: TCS | E1: BPCL | F1: GOLDBEES
A2: =Summary!A2 -> War begins | B2: =IF(Summary!B2="","",Summary!B2-Summary!$G2) -> 0.013877639 | C2: =IF(Summary!C2="","",Summary!C2-Summary!$G2) -> 0.065297773 | D2: =IF(Summary!D2="","",Summary!D2-Summary!$G2) -> 0.0039897036 | E2: =IF(Summary!E2="","",Summary!E2-Summary!$G2) -> -0.095065398 | F2: =IF(Summary!F2="","",Summary!F2-Summary!$G2) -> 0.04379775
A3: =Summary!A3 -> Ceasefire announced | B3: =IF(Summary!B3="","",Summary!B3-Summary!$G3) -> -0.044587029 | C3: =IF(Summary!C3="","",Summary!C3-Summary!$G3) -> 0.068794468 | D3: =IF(Summary!D3="","",Summary!D3-Summary!$G3) -> -0.041955825 | E3: =IF(Summary!E3="","",Summary!E3-Summary!$G3) -> 0.071039175 | F3: =IF(Summary!F3="","",Summary!F3-Summary!$G3) -> -0.02096736
A4: =Summary!A4 -> Brent $111 / rupee record low | B4: =IF(Summary!B4="","",Summary!B4-Summary!$G4) -> -0.064225092 | C4: =IF(Summary!C4="","",Summary!C4-Summary!$G4) -> 0.092766413 | D4: =IF(Summary!D4="","",Summary!D4-Summary!$G4) -> -0.035782468 | E4: =IF(Summary!E4="","",Summary!E4-Summary!$G4) -> 0.0060123412 | F4: =IF(Summary!F4="","",Summary!F4-Summary!$G4) -> 0.017607641
A5: =Summary!A5 -> Renewed US strikes | B5: =IF(Summary!B5="","",Summary!B5-Summary!$G5) -> 0.033537727 | C5: =IF(Summary!C5="","",Summary!C5-Summary!$G5) -> 0.023775254 | D5: =IF(Summary!D5="","",Summary!D5-Summary!$G5) -> 0.064062216 | E5: =IF(Summary!E5="","",Summary!E5-Summary!$G5) -> -0.013185173 | F5: =IF(Summary!F5="","",Summary!F5-Summary!$G5) -> -0.0077184016
A6: =Summary!A6 -> Sensex 2026 low | B6: =IF(Summary!B6="","",Summary!B6-Summary!$G6) -> -0.0064151886 | C6: =IF(Summary!C6="","",Summary!C6-Summary!$G6) -> -0.0055777966 | D6: =IF(Summary!D6="","",Summary!D6-Summary!$G6) -> 0.020674202 | E6: =IF(Summary!E6="","",Summary!E6-Summary!$G6) -> 0.00020004752 | F6: =IF(Summary!F6="","",Summary!F6-Summary!$G6) -> 0.0074593477
A8: AVERAGE (events 1-4, 5-day) | B8: =AVERAGE(B2:B5) -> -0.015349189 | C8: =AVERAGE(C2:C5) -> 0.062658477 | D8: =AVERAGE(D2:D5) -> -0.0024215934 | E8: =AVERAGE(E2:E5) -> -0.0077997636 | F8: =AVERAGE(F2:F5) -> 0.0081799073

Sheet Returns
A1: {=Prices!A4:A300} -> 46024.646 | B1: =Prices!B1 -> ONGC | C1: =Prices!C1 -> HAL | D1: =Prices!D1 -> TCS | E1: =Prices!E1 -> BPCL | F1: =Prices!F1 -> GOLDBEES | G1: =Prices!G1 -> NIFTY | H1: =Prices!H1
A2: 46027.646 | B2: {=IF(Prices!B4:B300="","",Prices!B4:B300/Prices!B3:B299-1)} -> 0.014793645 | C2: {=IF(Prices!C4:C300="","",Prices!C4:C300/Prices!C3:C299-1)} -> 0.0045248869 | D2: {=IF(Prices!D4:D300="","",Prices!D4:D300/Prices!D3:D299-1)} -> 0.0072194336 | E2: {=IF(Prices!E4:E300="","",Prices!E4:E300/Prices!E3:E299-1)} -> -0.0001310616 | F2: {=IF(Prices!F4:F300="","",Prices!F4:F300/Prices!F3:F299-1)} -> 0.011762577 | G2: {=IF(Prices!G4:G300="","",Prices!G4:G300/Prices!G3:G299-1)} -> 0.0069607654 | I2: Annualized volatility: | J2: =STDEV(B2:B187)*SQRT(252) -> 0.26540779
A3: 46028.646 | B3: -0.013956763 | C3: 0.024514464 | D3: -0.010643861 | E3: -0.0093065933 | F3: 0.0098372384 | G3: -0.0029720588 | I3: Beta vs Nifty | J3: =SLOPE(B2:B187, $G2:$G187) -> -0.057078681
A4: 46029.646 | B4: 0.015960351 | C4: -0.0022315017 | D4: 0.012344144 | E4: -0.018788039 | F4: 0.001948282 | G4: -0.0027275879 | I4: Correlation with Nifty: | J4: =CORREL(B2:B187, $G2:$G187) -> -0.031727592
A5: 46030.646 | B5: -0.011699533 | C5: 0.0020150576 | D5: 0.012224338 | E5: -0.0070118662 | F5: -0.0020328796 | G5: -0.0014496518
A6: 46031.646 | B6: -0.031958504 | C6: -0.010010828 | D6: -0.027824979 | E6: -0.037072243 | F6: -0.0054910991 | G6: -0.010095349
A7: 46034.646 | B7: 0.011537464 | C7: -0.0039510692 | D7: 0.0012172665 | E7: -0.0011281907 | F7: 0.011755277 | G7: -0.0074796585
A8: 46035.646 | B8: 0.0069204152 | C8: 0.012617377 | D8: 0.0099133362 | E8: 0.012988847 | F8: 0.027726433 | G8: 0.0041641845
A9: 46036.646 | B9: 0.034236986 | C9: -0.014606941 | D9: 0.0087665144 | E9: -0.010174216 | F9: -0.003340185 | G9: -0.0022469732
A10: 46038.646 | B10: 0.018254164 | C10: 0.0020213817 | D10: -0.023102815 | E10: 0.0050689946 | F10: 0.014092979 | G10: -0.002592073
A11: 46041.646 | B11: -0.0042702333 | C11: -0.0073295378 | D11: 0.0044479248 | E11: 0.017652003 | F11: -0.0019489874 | G11: 0.0011201764
A12: 46042.646 | B12: -0.016425942 | C12: 0.017070472 | D12: -0.013440609 | E12: -0.0053689427 | F12: 0.028188147 | G12: -0.0042363399
A13: 46043.646 | B13: -0.011188351 | C13: -0.033101703 | D13: -0.01937666 | E13: -0.016747405 | F13: 0.039306358 | G13: -0.013796877
A14: 46044.646 | B14: 0.0082366155 | C14: -0.021996694 | D14: 0.0065435322 | E14: -0.0091497748 | F14: 0.072382012 | G14: -0.0029723571
A15: 46045.646 | B15: 0.006766514 | C15: 0.022021881 | D15: 0.0089028374 | E15: 0.0062508879 | F15: -0.078758243 | G15: 0.0052628441
A16: 46049.646 | B16: 0.0059833613 | C16: -0.010911513 | D16: 0.0038407821 | E16: -0.014118311 | F16: 0.02477079 | G16: -0.0095393813
... A186: 46301.646 | B186: 0.011377434 | C186: 0.01717018 | D186: 0.018987952 | E186: -0.012142382 | F186: 0.0012352796 | G186: 0.0059673668
B187: -0.0031124944 | C187: 0.029059829 | D187: -0.0068104427 | E187: 0.011954875 | F187: -0.00098700444 | G187: 0.0097691276
